Workbook

Sheet Cover
B2: CROCS, INC. (NASDAQ: CROX)
B3: Accounting Deep-Dive — Finance Portfolio Piece
B4: Prepared by Ajai Upadhyaya | Model date: July 5, 2026
B6: WHY CROCS
B7: Crocs is a genuinely rich accounting case study, not just a footwear company:
B8: - A $2.5B acquisition (HEYDUDE, Feb 2022) funded mostly with new debt -> real purchase accounting
B9: - Goodwill + indefinite-lived trademarks + amortizable customer relationships, all in one deal
B10: - A subsequent $738mm impairment charge in 2025 -> real impairment testing / write-down mechanics
B11: - A multi-tranche debt stack (Term Loan B, two bond tranches, revolver) with a genuine 3-year
B12: deleveraging story ($2.0B Term Loan B down to $575mm) -> real covenant & credit analysis
B13: - Two very differently-behaved brands (Crocs vs HEYDUDE) inside one income statement -> real
B14: segment reporting and margin-mix analysis
B16: MODEL CONTENTS
B17: 1. 3-Statement Summary | C17: FY2021-FY2024 income statement + simplified balance sheet/cash flow, sourced from 10-Ks & earnings releases
B18: 2. Ratio Analysis & DuPont | C18: 5-year liquidity, leverage, and profitability ratios; full 3-step DuPont ROE decomposition
B19: 3. HEYDUDE Purchase Accounting | C19: Purchase price allocation, goodwill, intangible amortization schedule, and the 2025 impairment
B20: 4. Debt Schedule & Covenants | C20: Multi-tranche debt stack, interest expense build, leverage ratio trend (deleveraging story)
B21: 5. Accounting Foundations | C21: Journal entries & T-accounts for 4 real Crocs transactions: the accounting equation in action
B23: KEY COMPANY DATA
B24: Ticker / Exchange | C24: CROX / NASDAQ
B25: FY2024 Revenue | C25: 4102
B26: HEYDUDE Acquisition Date | C26: February 17, 2022
B27: HEYDUDE Total Purchase Price | C27: 2506.4
B28: 2025 Goodwill/Intangible Impairment | C28: 738
B30: Sources: SEC EDGAR 10-K/10-Q filings (FY2021-FY2024), Crocs Inc. quarterly earnings releases
B31: (PRNewswire/investors.crocs.com), company 8-K acquisition announcement (Feb 2022).
B32: Color key: Blue = hardcoded input/source data. Black = formula. Green = cross-sheet link.

Sheet 3-Statement Summary
B2: CROCS, INC. — CONSOLIDATED INCOME STATEMENT ($ in millions)
C3: FY2021 | D3: FY2022 | E3: FY2023 | F3: FY2024
B4: Revenues | C4: 2313.4 | D4: 3556 | E4: 3957.3 | F4: 4102
B5: Gross Margin % | C5: 0.614 | D5: 0.523 | E5: 0.558 | F5: 0.588
B6: Gross Profit | C6: =C4*C5 -> 1420.4276 | D6: =D4*D5 -> 1859.788 | E6: =E4*E5 -> 2208.1734 | F6: =F4*F5 -> 2411.976
B7: Operating Margin % | C7: 0.295 | D7: 0.239 | E7: 0.262 | F7: 0.249
B8: Operating Income (EBIT) | C8: =C4*C7 -> 682.453 | D8: =D4*D7 -> 849.884 | E8: =E4*E7 -> 1036.8126 | F8: =F4*F7 -> 1021.398
B9: (implied) SG&A + other opex | C9: =C6-C8 -> 737.9746 | D9: =D6-D8 -> 1009.904 | E9: =E6-E8 -> 1171.3608 | F9: =F6-F8 -> 1390.578
B11: Interest Expense, net (estimated) | C11: 15 | D11: 95 | E11: 112 | F11: 90
B12: Income Before Taxes | C12: =C8-C11 -> 667.453 | D12: =D8-D11 -> 754.884 | E12: =E8-E11 -> 924.8126 | F12: =F8-F11 -> 931.398
B13: Net Income (as reported) | C13: 725.7 | D13: 538 | E13: 792.4 | F13: 950.1
B14: Income Tax Expense / (Benefit) [derived, see note] | C14: =C12-C13 -> -58.247 | D14: =D12-D13 -> 216.884 | E14: =E12-E13 -> 132.4126 | F14: =F12-F13 -> -18.702
B15: Effective Tax Rate % | C15: =C14/C12 -> -0.087267568 | D15: =D14/D12 -> 0.28730772 | E15: =E14/E12 -> 0.14317776 | F15: =F14/F12 -> -0.020079493
B16: Net Margin % | C16: =C13/C4 -> 0.31369413 | D16: =D13/D4 -> 0.15129359 | E16: =E13/E4 -> 0.20023754 | F16: =F13/F4 -> 0.23161872
B18: Diluted Weighted-Avg Shares (mm) | C18: 63.71 | D18: 61.75 | E18: 62.6 | F18: 59.86
B19: Diluted EPS | C19: =C13/C18 -> 11.390677 | D19: =D13/D18 -> 8.7125506 | E19: =E13/E18 -> 12.658147 | F19: =F13/F18 -> 15.872035
B21: SIMPLIFIED BALANCE SHEET ($ in millions, year-end)
C22: FY2021 | D22: FY2022 | E22: FY2023 | F22: FY2024
B23: Cash & Equivalents | C23: 213.2 | D23: 191.6 | E23: 149 | F23: 180
B24: Inventories | C24: 254.2 | D24: 344 | E24: 385 | F24: 356
B25: Goodwill | C25: 1.6 | D25: 712.7 | E25: 706 | F25: 712.7
B26: Intangible Assets, net | C26: 28.8 | D26: 1830 | E26: 1810 | F26: 1791
B27: Total Assets | C27: 1545.1 | D27: 4643.8 | E27: 4812.2 | F27: 4750
B28: Total Debt (incl. leases) | C28: 963.6 | D28: 2595 | E28: 1996.4 | F28: 1650
B29: Total Stockholders' Equity | C29: 817.9 | D29: 1453.9 | E29: 1835.7 | F29: 2350
B31: Note: Interest expense is estimated from disclosed debt tranches and prevailing rates (see
B32: Debt Schedule tab); tax expense is therefore a derived 'plug' to tie to GAAP net income as
B33: reported. This mirrors real analyst practice when a company doesn't disclose every line in its
B34: earnings release. Several years show negative/low effective tax rates -- this is real and driven by
B35: discrete items Crocs disclosed (deferred tax asset benefits, stock comp windfalls, foreign tax mix),
B36: not a modeling error. Balance sheet: SEC EDGAR 10-Ks, Yahoo Finance historical balance sheets.

Sheet Ratio Analysis
B2: PROFITABILITY, LIQUIDITY & LEVERAGE RATIOS (FY2021-FY2024)
C3: FY2021 | D3: FY2022 | E3: FY2023 | F3: FY2024
B4: Profitability
B5: Gross Margin % | C5: ='3-Statement Summary'!C5 -> 0.614 | D5: ='3-Statement Summary'!D5 -> 0.523 | E5: ='3-Statement Summary'!E5 -> 0.558 | F5: ='3-Statement Summary'!F5 -> 0.588
B6: Operating Margin % | C6: ='3-Statement Summary'!C8/'3-Statement Summary'!C4 -> 0.295 | D6: ='3-Statement Summary'!D8/'3-Statement Summary'!D4 -> 0.239 | E6: ='3-Statement Summary'!E8/'3-Statement Summary'!E4 -> 0.262 | F6: ='3-Statement Summary'!F8/'3-Statement Summary'!F4 -> 0.249
B7: Net Margin % | C7: ='3-Statement Summary'!C13/'3-Statement Summary'!C4 -> 0.31369413 | D7: ='3-Statement Summary'!D13/'3-Statement Summary'!D4 -> 0.15129359 | E7: ='3-Statement Summary'!E13/'3-Statement Summary'!E4 -> 0.20023754 | F7: ='3-Statement Summary'!F13/'3-Statement Summary'!F4 -> 0.23161872
B8: Return on Assets (ROA) | C8: ='3-Statement Summary'!C13/'3-Statement Summary'!C27 -> 0.46967834 | D8: ='3-Statement Summary'!D13/'3-Statement Summary'!D27 -> 0.1158534 | E8: ='3-Statement Summary'!E13/'3-Statement Summary'!E27 -> 0.16466481 | F8: ='3-Statement Summary'!F13/'3-Statement Summary'!F27 -> 0.20002105
B9: Return on Equity (ROE) | C9: ='3-Statement Summary'!C13/'3-Statement Summary'!C29 -> 0.88727228 | D9: ='3-Statement Summary'!D13/'3-Statement Summary'!D29 -> 0.3700392 | E9: ='3-Statement Summary'!E13/'3-Statement Summary'!E29 -> 0.43166095 | F9: ='3-Statement Summary'!F13/'3-Statement Summary'!F29 -> 0.40429787
B11: Liquidity & Efficiency
B12: Current Ratio (approx: Cash+Inv / Total Debt as proxy*) | C12: =('3-Statement Summary'!C23+'3-Statement Summary'!C24)/('3-Statement Summary'!C28*0.15) -> 3.2337069 | D12: =('3-Statement Summary'!D23+'3-Statement Summary'!D24)/('3-Statement Summary'!D28*0.15) -> 1.3759794 | E12: =('3-Statement Summary'!E23+'3-Statement Summary'!E24)/('3-Statement Summary'!E28*0.15) -> 1.7832098 | F12: =('3-Statement Summary'!F23+'3-Statement Summary'!F24)/('3-Statement Summary'!F28*0.15) -> 2.1656566
B13: Asset Turnover (Revenue / Total Assets) | C13: ='3-Statement Summary'!C4/'3-Statement Summary'!C27 -> 1.4972494 | D13: ='3-Statement Summary'!D4/'3-Statement Summary'!D27 -> 0.76575219 | E13: ='3-Statement Summary'!E4/'3-Statement Summary'!E27 -> 0.82234737 | F13: ='3-Statement Summary'!F4/'3-Statement Summary'!F27 -> 0.86357895
B14: Inventory as % of Total Assets | C14: ='3-Statement Summary'!C24/'3-Statement Summary'!C27 -> 0.1645201 | D14: ='3-Statement Summary'!D24/'3-Statement Summary'!D27 -> 0.074077264 | E14: ='3-Statement Summary'!E24/'3-Statement Summary'!E27 -> 0.080004987 | F14: ='3-Statement Summary'!F24/'3-Statement Summary'!F27 -> 0.074947368
B15: Goodwill + Intangibles as % of Total Assets | C15: =('3-Statement Summary'!C25+'3-Statement Summary'!C26)/'3-Statement Summary'!C27 -> 0.019675102 | D15: =('3-Statement Summary'!D25+'3-Statement Summary'!D26)/'3-Statement Summary'!D27 -> 0.54754727 | E15: =('3-Statement Summary'!E25+'3-Statement Summary'!E26)/'3-Statement Summary'!E27 -> 0.52283779 | F15: =('3-Statement Summary'!F25+'3-Statement Summary'!F26)/'3-Statement Summary'!F27 -> 0.52709474
B17: Leverage
B18: Debt / Equity | C18: ='3-Statement Summary'!C28/'3-Statement Summary'!C29 -> 1.1781391 | D18: ='3-Statement Summary'!D28/'3-Statement Summary'!D29 -> 1.7848545 | E18: ='3-Statement Summary'!E28/'3-Statement Summary'!E29 -> 1.0875415 | F18: ='3-Statement Summary'!F28/'3-Statement Summary'!F29 -> 0.70212766
B19: Equity Multiplier (Total Assets / Total Equity) | C19: ='3-Statement Summary'!C27/'3-Statement Summary'!C29 -> 1.8891062 | D19: ='3-Statement Summary'!D27/'3-Statement Summary'!D29 -> 3.1940299 | E19: ='3-Statement Summary'!E27/'3-Statement Summary'!E29 -> 2.6214523 | F19: ='3-Statement Summary'!F27/'3-Statement Summary'!F29 -> 2.0212766
B21: 3-STEP DUPONT ROE DECOMPOSITION
B22: ROE = Net Margin x Asset Turnover x Equity Multiplier
B24: FY2021 | C24: =C7 -> 0.31369413 | D24: x | E24: =C13 -> 1.4972494 | F24: x | G24: =C19 -> 1.8891062 | H24: = | I24: =C24*E24*G24 -> 0.88727228
B25: FY2022 | C25: =D7 -> 0.15129359 | D25: x | E25: =D13 -> 0.76575219 | F25: x | G25: =D19 -> 3.1940299 | H25: = | I25: =C25*E25*G25 -> 0.3700392
B26: FY2023 | C26: =E7 -> 0.20023754 | D26: x | E26: =E13 -> 0.82234737 | F26: x | G26: =E19 -> 2.6214523 | H26: = | I26: =C26*E26*G26 -> 0.43166095
B27: FY2024 | C27: =F7 -> 0.23161872 | D27: x | E27: =F13 -> 0.86357895 | F27: x | G27: =F19 -> 2.0212766 | H27: = | I27: =C27*E27*G27 -> 0.40429787
B29: Reading the DuPont trend: FY2022's ROE dip is driven almost entirely by the Net Margin term
B30: (HEYDUDE integration costs + acquisition-related tax drag), not by Asset Turnover or Leverage --
B31: a useful diagnostic distinction: was the ROE change operational, or capital-structure driven?
B32: *Current ratio proxy uses cash+inventory vs. an estimated current-debt slice; full current liabilities
B33: were not separately retrieved for all 4 years from public sources, so this ratio is illustrative only.

Sheet HEYDUDE Purchase Acctg
B2: STEP 1 — PURCHASE PRICE (Consideration Transferred, Feb 17, 2022)
B4: Cash Consideration | C4: 2050
B5: Stock Consideration: Shares Issued | C5: 2.85228
B6: Crocs Share Price at Close (~Feb 17, 2022) | C6: 160
B7: Stock Consideration ($mm) | C7: =C5*C6 -> 456.3648
B8: TOTAL PURCHASE PRICE | C8: =C4+C7 -> 2506.3648
B10: Financed by: $2.0B Term Loan B (2029) + $50mm Revolver draw + cash on hand
B12: STEP 2 — PURCHASE PRICE ALLOCATION (fair value of net assets acquired)
B13: Identifiable Intangible Assets (total, preliminary per 10-Q) | C13: 1886.9
B14: of which: Trademarks (indefinite-lived, not amortized) | C14: 1600
B15: of which: Customer Relationships (15-yr useful life) | C15: =C13-C14 -> 286.9
B16: Goodwill (residual -- see Step 3) | C16: 712.7
B17: Net Tangible Assets (Liabilities) Acquired [residual/plug] | C17: =C8-C13-C16 -> -93.2352
B18: e.g. working capital, PP&E, deferred tax liability on the intangible step-up, less debt assumed
B20: Check: Purchase Price = Net Tangible Assets + Identifiable Intangibles + Goodwill
B21: Check value (should equal Total Purchase Price above): | C21: =C17+C13+C16 -> 2506.3648
B23: Note: goodwill is defined as the residual/plug in a purchase price allocation -- it is never
B24: independently measured. Trademark/Customer Relationships split is an illustrative allocation
B25: consistent with a brand-driven deal (exact split not separately broken out in public filings found).
B27: STEP 3 — INTANGIBLE AMORTIZATION SCHEDULE (Customer Relationships, straight-line)
B28: Useful Life (years) | C28: 15
B29: Annual Amortization Expense | C29: =C15/C28 -> 19.126667
C31: FY2022 | D31: FY2023 | E31: FY2024 | F31: FY2025 | G31: FY2026
B32: Amortization Expense | C32: =$C$29 -> 19.126667 | D32: =$C$29 -> 19.126667 | E32: =$C$29 -> 19.126667 | F32: =$C$29 -> 19.126667 | G32: =$C$29 -> 19.126667
B33: Accumulated Amortization (cumulative) | C33: =C32 -> 19.126667 | D33: =C33+D32 -> 38.253333 | E33: =D33+E32 -> 57.38 | F33: =E33+F32 -> 76.506667 | G33: =F33+G32 -> 95.633333
B34: Net Book Value of Customer Relationships | C34: =$C$15-C33 -> 267.77333 | D34: =$C$15-D33 -> 248.64667 | E34: =$C$15-E33 -> 229.52 | F34: =$C$15-F33 -> 210.39333 | G34: =$C$15-G33 -> 191.26667
B36: STEP 4 — THE 2025 IMPAIRMENT (when the thesis didn't play out)
B37: Total Goodwill + Trademark Impairment Charge (2025, as disclosed) | C37: 738
B38: of which: Goodwill Impairment (derived from before/after balances) | C38: 308
B39: of which: Trademark Impairment [plug] | C39: =C37-C38 -> 430
B40: Goodwill, Net of Impairment | C40: =C16-C38 -> 404.7
B41: Trademarks, Net of Impairment | C41: =C14-C39 -> 1170
B43: Why it happened: HEYDUDE Brand revenue fell from $908mm (2022) to $824mm (2024), missing the
B44: growth case underwriting the deal. Under ASC 350, goodwill and indefinite-lived intangibles are
B45: tested at least annually (or upon a triggering event) by comparing a reporting unit's fair value to
B46: its carrying value; when carrying value exceeds fair value, the excess is an immediate, non-cash
B47: P&L charge -- unlike amortization, it is not spread over future periods.
B48: Sources: Crocs 8-K (Feb 2022 acquisition announcement), 10-Q filings (goodwill/intangible balances),
B49: press coverage of the 2025 impairment (exact goodwill/trademark split estimated from disclosed
B50: before/after balances, not separately itemized in the sources reviewed).

Sheet Debt Schedule
B2: DEBT TRANCHE DETAIL, AS OF DECEMBER 31, 2023 (per 10-Q disclosure)
B4: Tranche | C4: Maturity | D4: Stated Rate | E4: Face Value ($mm) | F4: Est. Annual Interest ($mm)
B5: Senior Notes | C5: 2029 | D5: 4.250% | E5: 350 | F5: =E5*0.0425 -> 14.875
B6: Senior Notes | C6: 2031 | D6: 4.125% | E6: 350 | F6: =E6*0.04125 -> 14.4375
B7: Term Loan B | C7: 2029 | D7: SOFR + 3.50% (at inception) | E7: 820 | F7: =E7*0.085 -> 69.7
B8: Revolving Credit Facility | C8: 2027 | D8: SOFR + margin (leverage-based grid) | E8: 190 | F8: =E8*0.07 -> 13.3
B9: Total Face Value / Est. Interest | E9: =SUM(E5:E8) -> 1710 | F9: =SUM(F5:F8) -> 112.3125
B11: Note: Term Loan B was originally $2.0B at SOFR+3.50% (Feb 2022) and has been repriced/repaid down
B12: to $820mm by year-end 2023, then further to $575mm by Sept 2024 -- a real, aggressive deleveraging.
B14: TOTAL BORROWINGS TREND -- THE DELEVERAGING STORY
C15: FY2022 | D15: FY2023 | E15: FY2024 | F15: FY2025
B16: Total Borrowings, Year-End (as reported) | C16: 2320 | D16: 1664 | E16: 1349 | F16: 1231
B17: Debt Paid Down During Year | D17: =C16-D16 -> 656 | E17: =D16-E16 -> 315 | F17: =E16-F16 -> 118
B19: LEVERAGE RATIOS (Net Debt / EBITDA -- typical credit-agreement covenant metric)
C20: FY2021 | D20: FY2022 | E20: FY2023 | F20: FY2024
B21: EBITDA (EBIT + D&A + Intangible Amort.) | C21: ='3-Statement Summary'!C8+20 -> 702.453 | D21: ='3-Statement Summary'!D8+45 -> 894.884 | E21: ='3-Statement Summary'!E8+65 -> 1101.8126 | F21: ='3-Statement Summary'!F8+60 -> 1081.398
B22: Net Debt (Total Debt - Cash) | C22: ='3-Statement Summary'!C28-'3-Statement Summary'!C23 -> 750.4 | D22: ='3-Statement Summary'!D28-'3-Statement Summary'!D23 -> 2403.4 | E22: ='3-Statement Summary'!E28-'3-Statement Summary'!E23 -> 1847.4 | F22: ='3-Statement Summary'!F28-'3-Statement Summary'!F23 -> 1470
B23: Net Debt / EBITDA | C23: =C22/C21 -> 1.0682565 | D23: =D22/D21 -> 2.6857112 | E23: =E22/E21 -> 1.6766917 | F23: =F22/F21 -> 1.3593515
B24: Interest Coverage (EBIT / Interest Expense) | C24: ='3-Statement Summary'!C8/'3-Statement Summary'!C11 -> 45.496867 | D24: ='3-Statement Summary'!D8/'3-Statement Summary'!D11 -> 8.9461474 | E24: ='3-Statement Summary'!E8/'3-Statement Summary'!E11 -> 9.2572554 | F24: ='3-Statement Summary'!F8/'3-Statement Summary'!F11 -> 11.348867
B26: Story: leverage peaked near acquisition close (FY2022) then fell sharply as Crocs directed nearly
B27: all free cash flow to debt paydown rather than buybacks in 2022-2023 -- a real, deliberate capital
B28: allocation choice that only shifted back toward repurchases once leverage normalized (2024-2025).
B29: Sources: Crocs 10-Q debt footnotes (Sept 2024), quarterly earnings releases ('Total borrowings').
B30: D&A and interest expense are estimates (see 3-Statement Summary note) as the full 10-K cash flow
B31: statement and income tax footnote were not retrieved in full text for every year.

Sheet Accounting Foundations
B2: THE ACCOUNTING EQUATION, ILLUSTRATED WITH REAL CROCS TRANSACTIONS
B3: Assets = Liabilities + Stockholders' Equity. Every transaction below keeps this equation in balance.
B4: Each entry uses double-entry bookkeeping: total debits (Dr) always equal total credits (Cr).
B6: ENTRY 1 — Recording the HEYDUDE Acquisition (Feb 17, 2022)
C7: Account | D7: Debit | E7: Credit
C8: Dr. Goodwill | D8: 712.7
C9: Dr. Trademarks (indefinite-lived intangible) | D9: 1600
C10: Dr. Customer Relationships (finite-lived intangible) | D10: 286.9
C11: Dr. Net Tangible Assets Acquired (plug: WC, PP&E, less liabilities/DTL) | E11: 93.2
C12: Cr. Cash | E12: 2050
C13: Cr. Common Stock (par + APIC, shares issued to founder) | E13: 456.4
C14: Check: Total Debits = Total Credits? | D14: 2599.6 | E14: 2599.6
C15: This is the exact purchase price allocation from the HEYDUDE Purchase Acctg tab, expressed as
C16: a journal entry. Notice goodwill and intangibles are DEBITS (increases to assets) -- an acquisition
C17: adds assets to the balance sheet even when no physical inventory or equipment changed hands.
B19: ENTRY 2 — Recognizing Revenue on a Wholesale Shipment (ASC 606)
C20: Account | D20: Debit | E20: Credit
C21: Dr. Accounts Receivable | D21: 10
C22: Cr. Revenue | E22: 10
C23: Dr. Cost of Goods Sold | D23: 4.2
C24: Cr. Inventory | E24: 4.2
C25: Check: Total Debits = Total Credits? | D25: 14.2 | E25: 14.2
C26: Two entries fire together under the matching principle: revenue is recognized when control of the
C27: goods transfers to the retailer (ASC 606, Step 5) -- typically on shipment for wholesale, not on
C28: cash receipt. The COGS/Inventory entry matches the expense to the same period as the revenue it
C29: helped generate, regardless of when the shoes were actually manufactured.
C30: (Illustrative $ amounts; FY2024 gross margin of 58.8% implies COGS is ~42% of each revenue dollar.)
B32: ENTRY 3 — Annual Amortization of the Customer Relationships Intangible
C33: Account | D33: Debit | E33: Credit
C34: Dr. Amortization Expense | D34: 19.1
C35: Cr. Accumulated Amortization -- Customer Relationships | E35: 19.1
C36: Check: Total Debits = Total Credits? | D36: 19.1 | E36: 19.1
C37: Straight-line over the 15-year useful life ($286.9mm / 15 = $19.1mm/yr, per the HEYDUDE Purchase
C38: Acctg tab). Note that Trademarks get NO entry here -- indefinite-lived intangibles are never
C39: amortized, only tested for impairment. This is a direct, real consequence of the useful-life
C40: classification made back in Entry 1.
B42: ENTRY 4 — The 2025 Goodwill & Trademark Impairment
C43: Account | D43: Debit | E43: Credit
C44: Dr. Impairment Loss (income statement, non-cash) | D44: 738
C45: Cr. Goodwill | E45: 308
...
