Workbook

Sheet Cover
B2: NIKE, INC. (NYSE: NKE)
B3: Equity Research & Valuation Model — Finance Portfolio Piece
B4: Prepared by Ajai Upadhyaya | Model date: July 5, 2026
B6: MODEL CONTENTS
B7: 1. Historical Financials | C7: FY2021–FY2025 income statement + FY2022–FY2025 cash flow, sourced from 10-K filings
B8: 2. CAPM & WACC | C8: Cost of equity/debt build using live risk-free rate, beta, and capital structure
B9: 3. DCF Valuation | C9: 5-year unlevered FCF projection, terminal value, sensitivity grid, implied share price
B10: 4. Trading Comparables | C10: EV/EBITDA and P/E benchmarking vs. Lululemon, Deckers, adidas, On Holding
B11: 5. Portfolio Optimization | C11: Two-asset Markowitz efficient frontier: NKE vs. athletic/apparel peer basket
B13: KEY MARKET DATA (as of July 2, 2026 close)
B14: Share Price | C14: 44.09
B15: Shares Outstanding (mm) | C15: 1481
B16: Market Capitalization ($mm) | C16: =C14*C15 -> 65297.29
B17: Beta (5Y Monthly, Yahoo Finance) | C17: 1.13
B18: 52-Week Range | C18: $40.00 - $80.17
B19: 10-Yr US Treasury Yield (Rf) | C19: 0.0449
B21: Sources: SEC EDGAR 10-K filings (FY2021–FY2025), NIKE Q4 FY2025/FY2026 earnings releases,
B22: Yahoo Finance, CNBC, Google Finance, U.S. Treasury (data as of dates noted in each cell).
B23: Color key: Blue = hardcoded input/source data. Black = formula. Green = cross-sheet link.

Sheet Historical FS
B2: NIKE, INC. — CONSOLIDATED INCOME STATEMENT ($ in millions, FY ends May 31)
C3: FY2021 | D3: FY2022 | E3: FY2023 | F3: FY2024 | G3: FY2025
B4: Revenues | C4: 44538 | D4: 46710 | E4: 51217 | F4: 51362 | G4: 46309 | I4: Source: SEC EDGAR 10-K filings FY2021-FY2025 (compiled via stock-analysis-on.net);
B5: Cost of Sales | C5: -24576 | D5: -25231 | E5: -28925 | F5: -28475 | G5: -26519 | I5: nke-20250531.htm, nke-20240531.htm, etc. Cash flow: Yahoo Finance / company 10-Ks.
B6: Gross Profit | C6: =C4+C5 -> 19962 | D6: =D4+D5 -> 21479 | E6: =E4+E5 -> 22292 | F6: =F4+F5 -> 22887 | G6: =G4+G5 -> 19790 | I6: D&A known only for FY2024 ($796mm per 10-K); other years estimated at same % of revenue.
B7: Gross Margin % | C7: =C6/C4 -> 0.44820154 | D7: =D6/D4 -> 0.45983729 | E7: =E6/E4 -> 0.43524611 | F7: =F6/F4 -> 0.44560181 | G7: =G6/G4 -> 0.42734674
B8: Demand Creation Expense | C8: -3114 | D8: -3850 | E8: -4060 | F8: -4285 | G8: -4689
B9: Operating Overhead Expense | C9: -9911 | D9: -10954 | E9: -12317 | F9: -12291 | G9: -11399
B10: Operating Income (EBIT) | C10: =C6+C8+C9 -> 6937 | D10: =D6+D8+D9 -> 6675 | E10: =E6+E8+E9 -> 5915 | F10: =F6+F8+F9 -> 6311 | G10: =G6+G8+G9 -> 3702
B11: Operating Margin % | C11: =C10/C4 -> 0.15575464 | D11: =D10/D4 -> 0.14290302 | E11: =E10/E4 -> 0.115489 | F11: =F10/F4 -> 0.12287294 | G11: =G10/G4 -> 0.079941264
B12: Interest Income (Expense), Net | C12: -262 | D12: -205 | E12: 6 | F12: 161 | G12: 107
B13: Other Income (Expense), Net | C13: -14 | D13: 181 | E13: 280 | F13: 228 | G13: 76
B14: Income Before Income Taxes | C14: =C10+C12+C13 -> 6661 | D14: =D10+D12+D13 -> 6651 | E14: =E10+E12+E13 -> 6201 | F14: =F10+F12+F13 -> 6700 | G14: =G10+G12+G13 -> 3885
B15: Income Tax Expense | C15: -934 | D15: -605 | E15: -1131 | F15: -1000 | G15: -666
B16: Effective Tax Rate % | C16: =-C15/C14 -> 0.14021919 | D16: =-D15/D14 -> 0.090963765 | E16: =-E15/E14 -> 0.18238994 | F16: =-F15/F14 -> 0.14925373 | G16: =-G15/G14 -> 0.17142857
B17: Net Income | C17: =C14+C15 -> 5727 | D17: =D14+D15 -> 6046 | E17: =E14+E15 -> 5070 | F17: =F14+F15 -> 5700 | G17: =G14+G15 -> 3219
B18: Net Margin % | C18: =C17/C4 -> 0.12858682 | D18: =D17/D4 -> 0.12943695 | E18: =E17/E4 -> 0.09899057 | F18: =F17/F4 -> 0.11097699 | G18: =G17/G4 -> 0.069511326
B20: Diluted Weighted-Avg Shares (mm) | C20: 1615 | D20: 1578 | E20: 1553 | F20: 1519 | G20: 1479
B21: Diluted EPS | C21: =C17/C20 -> 3.54613 | D21: =D17/D20 -> 3.8314322 | E21: =E17/E20 -> 3.2646491 | F21: =F17/F20 -> 3.7524687 | G21: =G17/G20 -> 2.1764706
B23: Depreciation & Amortization | C23: =C4*($F$23/$F$4) -> 690.24275 | D23: =D4*($F$23/$F$4) -> 723.90405 | E23: =E4*($F$23/$F$4) -> 793.75281 | F23: 796 | G23: =G4*($F$23/$F$4) -> 717.68942
B24: EBITDA (EBIT + D&A) | C24: =C10+C23 -> 7627.2427 | D24: =D10+D23 -> 7398.9041 | E24: =E10+E23 -> 6708.7528 | F24: =F10+F23 -> 7107 | G24: =G10+G23 -> 4419.6894
B26: CASH FLOW SUMMARY ($ in millions) — Source: Yahoo Finance / company 10-Ks
D27: FY2022 | E27: FY2023 | F27: FY2024 | G27: FY2025
B28: Cash from Operations | D28: 5188 | E28: 5841 | F28: 7429 | G28: 3698
B29: Capital Expenditures | D29: -758 | E29: -969 | F29: -812 | G29: -430
B30: Free Cash Flow | D30: =D28+D29 -> 4430 | E30: =E28+E29 -> 4872 | F30: =F28+F29 -> 6617 | G30: =G28+G29 -> 3268

Sheet CAPM & WACC
B2: COST OF EQUITY — CAPITAL ASSET PRICING MODEL
B4: Risk-Free Rate (10-Yr US Treasury) | C4: =Cover!$C$19 -> 0.0449
B5: Equity Risk Premium (Damodaran implied ERP, US) | C5: 0.05
B6: NKE Beta (5Y Monthly vs. S&P 500) | C6: =Cover!$C$17 -> 1.13
B7: Cost of Equity = Rf + Beta x ERP | C7: =C4+C6*C5 -> 0.1014
B9: COST OF DEBT
B10: Total Debt ($mm, FY2025 10-K) | C10: 7966
B11: Interest Expense ($mm, FY2025 10-K) | C11: 297
B12: Pre-Tax Cost of Debt = Interest Exp / Total Debt | C12: =C11/C10 -> 0.037283455
B13: Effective Tax Rate (avg FY2023-FY2025, from Historical FS) | C13: =AVERAGE('Historical FS'!E16:G16) -> 0.16769075
B14: After-Tax Cost of Debt | C14: =C12*(1-C13) -> 0.031031364
B16: CAPITAL STRUCTURE & WACC
B17: Market Value of Equity ($mm) | C17: =Cover!$C$16 -> 65297.29
B18: Market Value of Debt ($mm) | C18: =C10 -> 7966
B19: Total Capital | C19: =C17+C18 -> 73263.29
B20: Weight of Equity | C20: =C17/C19 -> 0.89126887
B21: Weight of Debt | C21: =C18/C19 -> 0.10873113
B23: WACC = We x CoE + Wd x CoD(after-tax) | C23: =C20*C7+C21*C14 -> 0.093748739
B25: Sources: Risk-free rate & beta linked from Cover tab (US Treasury, Yahoo Finance).
B26: ERP: Damodaran-style implied U.S. equity risk premium, ~5.0% typical estimate (mid-2026).
B27: Debt & interest expense: NIKE FY2025 10-K. Tax rate: 3-yr average of historical effective rate.

Sheet DCF Valuation
B2: NIKE — 5-YEAR UNLEVERED FREE CASH FLOW PROJECTION ($ in millions)
C3: FY2025A | D3: FY2026E | E3: FY2027E | F3: FY2028E | G3: FY2029E | H3: FY2030E
B4: ASSUMPTIONS (blue = editable input)
B5: Revenue Growth % | C5: n/a | D5: 0.01 | E5: 0.03 | F5: 0.04 | G5: 0.04 | H5: 0.04
B6: EBIT Margin % | C6: ='Historical FS'!G10/'Historical FS'!G4 -> 0.079941264 | D6: 0.09 | E6: 0.1 | F6: 0.11 | G6: 0.12 | H6: 0.125
B7: Tax Rate % (linked from CAPM & WACC) | D7: ='CAPM & WACC'!$C$13 -> 0.16769075 | E7: ='CAPM & WACC'!$C$13 -> 0.16769075 | F7: ='CAPM & WACC'!$C$13 -> 0.16769075 | G7: ='CAPM & WACC'!$C$13 -> 0.16769075 | H7: ='CAPM & WACC'!$C$13 -> 0.16769075
B8: D&A % of Revenue | D8: 0.016 | E8: 0.016 | F8: 0.016 | G8: 0.016 | H8: 0.016
B9: Capex % of Revenue | D9: 0.015 | E9: 0.015 | F9: 0.015 | G9: 0.015 | H9: 0.015
B10: Increase in NWC % of Revenue | D10: 0.003 | E10: 0.003 | F10: 0.003 | G10: 0.003 | H10: 0.003
B12: PROJECTION
B13: Revenue | C13: ='Historical FS'!G4 -> 46309 | D13: =C13*(1+D5) -> 46772.09 | E13: =D13*(1+E5) -> 48175.253 | F13: =E13*(1+F5) -> 50102.263 | G13: =F13*(1+G5) -> 52106.353 | H13: =G13*(1+H5) -> 54190.607
B14: EBIT | C14: =C13*C6 -> 3702 | D14: =D13*D6 -> 4209.4881 | E14: =E13*E6 -> 4817.5253 | F14: =F13*F6 -> 5511.2489 | G14: =G13*G6 -> 6252.7624 | H14: =H13*H6 -> 6773.8259
B15: NOPAT = EBIT x (1 - tax) | D15: =D14*(1-D7) -> 3503.5959 | E15: =E14*(1-E7) -> 4009.6709 | F15: =F14*(1-F7) -> 4587.0635 | G15: =G14*(1-G7) -> 5204.232 | H15: =H14*(1-H7) -> 5637.918
B16: + D&A | D16: =D13*D8 -> 748.35344 | E16: =E13*E8 -> 770.80404 | F16: =F13*F8 -> 801.6362 | G16: =G13*G8 -> 833.70165 | H16: =H13*H8 -> 867.04972
B17: - Capex | D17: =-D13*D9 -> -701.58135 | E17: =-E13*E9 -> -722.62879 | F17: =-F13*F9 -> -751.53394 | G17: =-G13*G9 -> -781.5953 | H17: =-H13*H9 -> -812.85911
B18: - Increase in NWC | D18: =-D13*D10 -> -140.31627 | E18: =-E13*E10 -> -144.52576 | F18: =-F13*F10 -> -150.30679 | G18: =-G13*G10 -> -156.31906 | H18: =-H13*H10 -> -162.57182
B19: Unlevered Free Cash Flow | D19: =D15+D16+D17+D18 -> 3410.0517 | E19: =E15+E16+E17+E18 -> 3913.3204 | F19: =F15+F16+F17+F18 -> 4486.8589 | G19: =G15+G16+G17+G18 -> 5100.0193 | H19: =H15+H16+H17+H18 -> 5529.5368
B20: Discount Period (t) | D20: 1 | E20: 2 | F20: 3 | G20: 4 | H20: 5
B21: Discount Factor @ WACC | D21: =1/(1+'CAPM & WACC'!$C$23)^D20 -> 0.91428677 | E21: =1/(1+'CAPM & WACC'!$C$23)^E20 -> 0.83592029 | F21: =1/(1+'CAPM & WACC'!$C$23)^F20 -> 0.76427086 | G21: =1/(1+'CAPM & WACC'!$C$23)^G20 -> 0.69876274 | H21: =1/(1+'CAPM & WACC'!$C$23)^H20 -> 0.63886953
B22: PV of Unlevered FCF | D22: =D19*D21 -> 3117.7652 | E22: =E19*E21 -> 3271.2239 | F22: =F19*F21 -> 3429.1756 | G22: =G19*G21 -> 3563.7035 | H22: =H19*H21 -> 3532.6526
B24: ENTERPRISE VALUE BRIDGE
B25: Terminal Growth Rate (g) | C25: 0.025
B26: Terminal Value (Gordon Growth, end of FY2030) | C26: =H19*(1+C25)/('CAPM & WACC'!$C$23-C25) -> 82441.879
B27: PV of Terminal Value | C27: =C26*H21 -> 52669.604
B28: Sum of PV of FCF (FY26-FY30) | C28: =SUM(D22:H22) -> 16914.521
B29: Enterprise Value | C29: =C28+C27 -> 69584.125
B31: Less: Total Debt ($mm, FY2025) | C31: 7966
B32: Plus: Cash & Short-Term Investments ($mm, FY2025) | C32: 9200
B33: Implied Equity Value | C33: =C29-C31+C32 -> 70818.125
B34: Diluted Shares Outstanding (mm) | C34: =Cover!$C$15 -> 1481
B35: IMPLIED SHARE PRICE | C35: =C33/C34 -> 47.817775
B36: Current Share Price | C36: =Cover!$C$14 -> 44.09
B37: Implied Upside / (Downside) | C37: =C35/C36-1 -> 0.084549217
B39: Sources: FY2025 actuals from Historical FS tab. Forward assumptions reflect a gradual margin
B40: recovery consistent with NIKE's 'Win Now' turnaround plan (management commentary, Q4 FY2025/26
B41: earnings calls). Debt/cash from FY2025 10-K. WACC and tax rate linked from CAPM & WACC tab.
B42: SENSITIVITY: IMPLIED SHARE PRICE — WACC (rows) x TERMINAL GROWTH (columns)
B43: WACC \ g | C43: 0.015 | D43: 0.02 | E43: 0.025 | F43: 0.03 | G43: 0.035
B44: =('CAPM & WACC'!$C$23-0.01) -> 0.083748739 | C44: =(D19/(1+('CAPM & WACC'!$C$23-0.01))^1+E19/(1+('CAPM & WACC'!$C$23-0.01))^2+F19/(1+('CAPM & WACC'!$C$23-0.01))^3+G19/(1+('CAPM & WACC'!$C$23-0.01))^4+H19/(1+('CAPM & WACC'!$C$23-0.01))^5+(H19*(1+$C$43)/(('CAPM & WACC'!$C$23-0.01)-$C$43))/(1+('CAPM & WACC'!$C$23-0.01))^5-C31+C32)/C34 -> 49.453046 | D44: =(D19/(1+('CAPM & WACC'!$C$23-0.01))^1+E19/(1+('CAPM & WACC'!$C$23-0.01))^2+F19/(1+('CAPM & WACC'!$C$23-0.01))^3+G19/(1+('CAPM & WACC'!$C$23-0.01))^4+H19/(1+('CAPM & WACC'!$C$23-0.01))^5+(H19*(1+$D$43)/(('CAPM & WACC'!$C$23-0.01)-$D$43))/(1+('CAPM & WACC'!$C$23-0.01))^5-C31+C32)/C34 -> 52.540873 | E44: =(D19/(1+('CAPM & WACC'!$C$23-0.01))^1+E19/(1+('CAPM & WACC'!$C$23-0.01))^2+F19/(1+('CAPM & WACC'!$C$23-0.01))^3+G19/(1+('CAPM & WACC'!$C$23-0.01))^4+H19/(1+('CAPM & WACC'!$C$23-0.01))^5+(H19*(1+$E$43)/(('CAPM & WACC'!$C$23-0.01)-$E$43))/(1+('CAPM & WACC'!$C$23-0.01))^5-C31+C32)/C34 -> 56.154299 | F44: =(D19/(1+('CAPM & WACC'!$C$23-0.01))^1+E19/(1+('CAPM & WACC'!$C$23-0.01))^2+F19/(1+('CAPM & WACC'!$C$23-0.01))^3+G19/(1+('CAPM & WACC'!$C$23-0.01))^4+H19/(1+('CAPM & WACC'!$C$23-0.01))^5+(H19*(1+$F$43)/(('CAPM & WACC'!$C$23-0.01)-$F$43))/(1+('CAPM & WACC'!$C$23-0.01))^5-C31+C32)/C34 -> 60.440005 | G44: =(D19/(1+('CAPM & WACC'!$C$23-0.01))^1+E19/(1+('CAPM & WACC'!$C$23-0.01))^2+F19/(1+('CAPM & WACC'!$C$23-0.01))^3+G19/(1+('CAPM & WACC'!$C$23-0.01))^4+H19/(1+('CAPM & WACC'!$C$23-0.01))^5+(H19*(1+$G$43)/(('CAPM & WACC'!$C$23-0.01)-$G$43))/(1+('CAPM & WACC'!$C$23-0.01))^5-C31+C32)/C34 -> 65.604854
B45: =('CAPM & WACC'!$C$23-0.005) -> 0.088748739 | C45: =(D19/(1+('CAPM & WACC'!$C$23-0.005))^1+E19/(1+('CAPM & WACC'!$C$23-0.005))^2+F19/(1+('CAPM & WACC'!$C$23-0.005))^3+G19/(1+('CAPM & WACC'!$C$23-0.005))^4+H19/(1+('CAPM & WACC'!$C$23-0.005))^5+(H19*(1+$C$43)/(('CAPM & WACC'!$C$23-0.005)-$C$43))/(1+('CAPM & WACC'!$C$23-0.005))^5-C31+C32)/C34 -> 46.005822 | D45: =(D19/(1+('CAPM & WACC'!$C$23-0.005))^1+E19/(1+('CAPM & WACC'!$C$23-0.005))^2+F19/(1+('CAPM & WACC'!$C$23-0.005))^3+G19/(1+('CAPM & WACC'!$C$23-0.005))^4+H19/(1+('CAPM & WACC'!$C$23-0.005))^5+(H19*(1+$D$43)/(('CAPM & WACC'!$C$23-0.005)-$D$43))/(1+('CAPM & WACC'!$C$23-0.005))^5-C31+C32)/C34 -> 48.626259 | E45: =(D19/(1+('CAPM & WACC'!$C$23-0.005))^1+E19/(1+('CAPM & WACC'!$C$23-0.005))^2+F19/(1+('CAPM & WACC'!$C$23-0.005))^3+G19/(1+('CAPM & WACC'!$C$23-0.005))^4+H19/(1+('CAPM & WACC'!$C$23-0.005))^5+(H19*(1+$E$43)/(('CAPM & WACC'!$C$23-0.005)-$E$43))/(1+('CAPM & WACC'!$C$23-0.005))^5-C31+C32)/C34 -> 51.657753 | F45: =(D19/(1+('CAPM & WACC'!$C$23-0.005))^1+E19/(1+('CAPM & WACC'!$C$23-0.005))^2+F19/(1+('CAPM & WACC'!$C$23-0.005))^3+G19/(1+('CAPM & WACC'!$C$23-0.005))^4+H19/(1+('CAPM & WACC'!$C$23-0.005))^5+(H19*(1+$F$43)/(('CAPM & WACC'!$C$23-0.005)-$F$43))/(1+('CAPM & WACC'!$C$23-0.005))^5-C31+C32)/C34 -> 55.205257 | G45: =(D19/(1+('CAPM & WACC'!$C$23-0.005))^1+E19/(1+('CAPM & WACC'!$C$23-0.005))^2+F19/(1+('CAPM & WACC'!$C$23-0.005))^3+G19/(1+('CAPM & WACC'!$C$23-0.005))^4+H19/(1+('CAPM & WACC'!$C$23-0.005))^5+(H19*(1+$G$43)/(('CAPM & WACC'!$C$23-0.005)-$G$43))/(1+('CAPM & WACC'!$C$23-0.005))^5-C31+C32)/C34 -> 59.412777
...

Sheet Trading Comps
B2: ATHLETIC APPAREL & FOOTWEAR — TRADING COMPARABLES (as of early July 2026)
B4: Company | C4: Ticker | D4: Price | E4: Shares (mm) | F4: Market Cap | G4: Total Debt | H4: Cash | I4: Enterprise Value | J4: Revenue (TTM) | K4: EBITDA (TTM) | L4: EV/EBITDA | M4: P/E (TTM)
B5: NIKE, Inc. | C5: NKE | D5: 44.09 | E5: 1481 | F5: =D5*E5 -> 65297.29 | G5: 7966 | H5: 9200 | I5: =F5+G5-H5 -> 64063.29 | J5: 46398 | K5: 4351 | L5: =I5/K5 -> 14.723808 | M5: 21
B6: Lululemon Athletica | C6: LULU | D6: 111.77 | E6: 115 | F6: =D6*E6 -> 12853.55 | G6: 300 | H6: 1500 | I6: =F6+G6-H6 -> 11653.55 | J6: 11200 | K6: 2580 | L6: =I6/K6 -> 4.5168798 | M6: 9
B7: Deckers Outdoor | C7: DECK | D7: 104.69 | E7: 145 | F7: =D7*E7 -> 15180.05 | G7: 0 | H7: 2100 | I7: =F7+G7-H7 -> 13080.05 | J7: 4700 | K7: 1150 | L7: =I7/K7 -> 11.373957 | M7: 18.5
B8: adidas AG (ADR) | C8: ADDYY | D8: 105.15 | E8: 195 | F8: =D8*E8 -> 20504.25 | G8: 2200 | H8: 1600 | I8: =F8+G8-H8 -> 21104.25 | J8: 25500 | K8: 3100 | L8: =I8/K8 -> 6.8078226 | M8: 22
B9: On Holding AG | C9: ONON | D9: 36.83 | E9: 145 | F9: =D9*E9 -> 5340.35 | G9: 100 | H9: 900 | I9: =F9+G9-H9 -> 4540.35 | J9: 3000 | K9: 500 | L9: =I9/K9 -> 9.0807 | M9: 45
B11: Peer Median (ex-NKE) EV/EBITDA | L11: =MEDIAN(L6:L9) -> 7.9442613
B12: Peer Median (ex-NKE) P/E | M12: =MEDIAN(M6:M9) -> 20.25
B14: IMPLIED NIKE VALUATION FROM PEER MULTIPLES
B15: Method | D15: Peer Multiple | E15: NKE Metric | F15: Implied EV | G15: Implied Equity Value | H15: Implied Share Price
B16: EV / EBITDA | D16: =L11 -> 7.9442613 | E16: =K5 -> 4351 | F16: =D16*E16 -> 34565.481 | G16: =F16-G5+H5 -> 35799.481 | H16: =G16/Cover!$C$15 -> 24.172506
B17: P / E (direct to equity) | D17: =M12 -> 20.25 | E17: ='Historical FS'!G17 -> 3219 | G17: =D17*E17 -> 65184.75 | H17: =G17/Cover!$C$15 -> 44.014011
B19: Cross-check vs. DCF implied share price: | H19: ='DCF Valuation'!C35 -> 47.817775
B21: Sources: Prices/shares/market data — Yahoo Finance, CNBC, Google Finance, TIKR (early July 2026).
B22: LULU EBITDA/revenue: stockanalysis.com. DECK, ADDYY, ONON: company FY2025 filings and TIKR comp screens.
B23: NKE Revenue/EBITDA TTM: CNBC quote page. Debt/cash figures approximate where ADR/FX-translated.

Sheet Portfolio Optimization
B2: MARKOWITZ TWO-ASSET EFFICIENT FRONTIER — NIKE vs. ATHLETIC/APPAREL PEER BASKET
B4: ASSET INPUTS (CAPM expected return; volatility sourced/estimated)
B5: Asset | C5: Beta | D5: Expected Return (CAPM) | E5: Ann. Volatility | F5: Source
B6: NIKE (NKE) | C6: 1.13 | D6: =Cover!$C$19+C6*'CAPM & WACC'!$C$5 -> 0.1014 | E6: 0.327 | F6: Beta: Yahoo Finance 5Y monthly. Vol: TradingView (4.53% wk x sqrt(52))
B7: Lululemon (LULU) | C7: 0.86 | D7: =Cover!$C$19+C7*'CAPM & WACC'!$C$5 -> 0.0879 | E7: 0.35 | F7: Beta: stockanalysis.com. Vol: estimated (elevated post-selloff)
B8: Deckers (DECK) | C8: 1.17 | D8: =Cover!$C$19+C8*'CAPM & WACC'!$C$5 -> 0.1034 | E8: 0.433 | F8: Beta: Google Finance. Vol: Simply Wall St (6% wk x sqrt(52))
B9: adidas (ADDYY) | C9: 0.9 | D9: =Cover!$C$19+C9*'CAPM & WACC'!$C$5 -> 0.0899 | E9: 0.28 | F9: Beta/vol: estimated, large diversified multinational profile
B10: On Holding (ONON) | C10: 1.5 | D10: =Cover!$C$19+C10*'CAPM & WACC'!$C$5 -> 0.1199 | E10: 0.45 | F10: Beta/vol: estimated, high-growth small-cap profile
B12: ESTIMATED CORRELATION MATRIX (sector co-movement assumption)
C13: NKE | D13: LULU | E13: DECK | F13: ADDYY | G13: ONON
B14: NKE | C14: 1 | D14: 0.55 | E14: 0.6 | F14: 0.5 | G14: 0.45
B15: LULU | C15: 0.55 | D15: 1 | E15: 0.5 | F15: 0.4 | G15: 0.45
B16: DECK | C16: 0.6 | D16: 0.5 | E16: 1 | F16: 0.45 | G16: 0.5
B17: ADDYY | C17: 0.5 | D17: 0.4 | E17: 0.45 | F17: 1 | G17: 0.4
B18: ONON | C18: 0.45 | D18: 0.45 | E18: 0.5 | F18: 0.4 | G18: 1
B20: COVARIANCE MATRIX = Corr(i,j) x Vol(i) x Vol(j)
C21: NKE | D21: LULU | E21: DECK | F21: ADDYY | G21: ONON
B22: NKE | C22: =C14*$E$6*$E$6 -> 0.106929 | D22: =D14*$E$6*$E$7 -> 0.0629475 | E22: =E14*$E$6*$E$8 -> 0.0849546 | F22: =F14*$E$6*$E$9 -> 0.04578 | G22: =G14*$E$6*$E$10 -> 0.0662175
B23: LULU | C23: =C15*$E$7*$E$6 -> 0.0629475 | D23: =D15*$E$7*$E$7 -> 0.1225 | E23: =E15*$E$7*$E$8 -> 0.075775 | F23: =F15*$E$7*$E$9 -> 0.0392 | G23: =G15*$E$7*$E$10 -> 0.070875
B24: DECK | C24: =C16*$E$8*$E$6 -> 0.0849546 | D24: =D16*$E$8*$E$7 -> 0.075775 | E24: =E16*$E$8*$E$8 -> 0.187489 | F24: =F16*$E$8*$E$9 -> 0.054558 | G24: =G16*$E$8*$E$10 -> 0.097425
B25: ADDYY | C25: =C17*$E$9*$E$6 -> 0.04578 | D25: =D17*$E$9*$E$7 -> 0.0392 | E25: =E17*$E$9*$E$8 -> 0.054558 | F25: =F17*$E$9*$E$9 -> 0.0784 | G25: =G17*$E$9*$E$10 -> 0.0504
B26: ONON | C26: =C18*$E$10*$E$6 -> 0.0662175 | D26: =D18*$E$10*$E$7 -> 0.070875 | E26: =E18*$E$10*$E$8 -> 0.097425 | F26: =F18*$E$10*$E$9 -> 0.0504 | G26: =G18*$E$10*$E$10 -> 0.2025
B29: PEER BASKET (equal-weighted 25% each: LULU, DECK, ADDYY, ONON)
B30: Basket Expected Return | C30: =AVERAGE(D7:D10) -> 0.100275
B31: Basket Variance = w'Cov w (peers only, w=0.25 each) | C31: =0.0625*D23+0.0625*E23+0.0625*F23+0.0625*G23+0.0625*D24+0.0625*E24+0.0625*F24+0.0625*G24+0.0625*D25+0.0625*E25+0.0625*F25+0.0625*G25+0.0625*D26+0.0625*E26+0.0625*F26+0.0625*G26 -> 0.085459688
B32: Basket Volatility (Std Dev) | C32: =SQRT(C31) -> 0.29233489
B33: Cov(NKE, Basket) | C33: =0.25*D22+0.25*E22+0.25*F22+0.25*G22 -> 0.0649749
B35: TWO-ASSET EFFICIENT FRONTIER (w = weight on NKE, 1-w on Peer Basket)
B36: Weight NKE | C36: Weight Basket | D36: Portfolio Return | E36: Portfolio Variance | F36: Portfolio Std Dev | G36: Sharpe Ratio
B37: 0 | C37: =1-B37 -> 1 | D37: =B37*$D$6+C37*$C$30 -> 0.100275 | E37: =B37^2*$C$22+C37^2*$C$31+2*B37*C37*$C$33 -> 0.085459688 | F37: =SQRT(E37) -> 0.29233489 | G37: =(D37-Cover!$C$19)/F37 -> 0.18942317
B38: 0.1 | C38: =1-B38 -> 0.9 | D38: =B38*$D$6+C38*$C$30 -> 0.1003875 | E38: =B38^2*$C$22+C38^2*$C$31+2*B38*C38*$C$33 -> 0.081987119 | F38: =SQRT(E38) -> 0.28633393 | G38: =(D38-Cover!$C$19)/F38 -> 0.19378598
B39: 0.2 | C39: =1-B39 -> 0.8 | D39: =B39*$D$6+C39*$C$30 -> 0.1005 | E39: =B39^2*$C$22+C39^2*$C$31+2*B39*C39*$C$33 -> 0.079763328 | F39: =SQRT(E39) -> 0.28242402 | G39: =(D39-Cover!$C$19)/F39 -> 0.19686711
B40: 0.3 | C40: =1-B40 -> 0.7 | D40: =B40*$D$6+C40*$C$30 -> 0.1006125 | E40: =B40^2*$C$22+C40^2*$C$31+2*B40*C40*$C$33 -> 0.078788315 | F40: =SQRT(E40) -> 0.28069256 | G40: =(D40-Cover!$C$19)/F40 -> 0.19848228
B41: 0.4 | C41: =1-B41 -> 0.6 | D41: =B41*$D$6+C41*$C$30 -> 0.100725 | E41: =B41^2*$C$22+C41^2*$C$31+2*B41*C41*$C$33 -> 0.079062079 | F41: =SQRT(E41) -> 0.2811798 | G41: =(D41-Cover!$C$19)/F41 -> 0.19853844
B42: 0.5 | C42: =1-B42 -> 0.5 | D42: =B42*$D$6+C42*$C$30 -> 0.1008375 | E42: =B42^2*$C$22+C42^2*$C$31+2*B42*C42*$C$33 -> 0.080584622 | F42: =SQRT(E42) -> 0.28387431 | G42: =(D42-Cover!$C$19)/F42 -> 0.19705024
B43: 0.6 | C43: =1-B43 -> 0.4 | D43: =B43*$D$6+C43*$C$30 -> 0.10095 | E43: =B43^2*$C$22+C43^2*$C$31+2*B43*C43*$C$33 -> 0.083355942 | F43: =SQRT(E43) -> 0.28871429 | G43: =(D43-Cover!$C$19)/F43 -> 0.19413656
B44: 0.7 | C44: =1-B44 -> 0.3 | D44: =B44*$D$6+C44*$C$30 -> 0.1010625 | E44: =B44^2*$C$22+C44^2*$C$31+2*B44*C44*$C$33 -> 0.08737604 | F44: =SQRT(E44) -> 0.29559438 | G44: =(D44-Cover!$C$19)/F44 -> 0.18999854
B45: 0.8 | C45: =1-B45 -> 0.2 | D45: =B45*$D$6+C45*$C$30 -> 0.101175 | E45: =B45^2*$C$22+C45^2*$C$31+2*B45*C45*$C$33 -> 0.092644915 | F45: =SQRT(E45) -> 0.30437627 | G45: =(D45-Cover!$C$19)/F45 -> 0.18488629
B46: 0.9 | C46: =1-B46 -> 0.1 | D46: =B46*$D$6+C46*$C$30 -> 0.1012875 | E46: =B46^2*$C$22+C46^2*$C$31+2*B46*C46*$C$33 -> 0.099162569 | F46: =SQRT(E46) -> 0.31490089 | G46: =(D46-Cover!$C$19)/F46 -> 0.17906428
B47: 1 | C47: =1-B47 -> 0 | D47: =B47*$D$6+C47*$C$30 -> 0.1014 | E47: =B47^2*$C$22+C47^2*$C$31+2*B47*C47*$C$33 -> 0.106929 | F47: =SQRT(E47) -> 0.327 | G47: =(D47-Cover!$C$19)/F47 -> 0.17278287
...
